[2024-11-05 22:30:13,594] [startdriver.py:33] [startdriver:get_driver] [INFO]- start app...
[2024-11-05 22:30:14,064] [semail.py:42] [semail:send_email] [ERROR]- (535, b'Error: authentication failed')
[2024-11-05 22:31:08,097] [startdriver.py:33] [startdriver:get_driver] [INFO]- start app...
[2024-11-05 22:31:08,351] [semail.py:42] [semail:send_email] [ERROR]- (535, b'Error: authentication failed')
[2024-11-05 22:32:04,977] [startdriver.py:33] [startdriver:get_driver] [INFO]- start app...
[2024-11-05 22:32:05,922] [semail.py:42] [semail:send_email] [ERROR]- (535, b'Error: authentication failed')
[2024-11-05 22:36:38,899] [startdriver.py:33] [startdriver:get_driver] [INFO]- start app...
[2024-11-05 22:46:53,724] [startdriver.py:33] [startdriver:get_driver] [INFO]- start app...
[2024-11-05 22:46:56,388] [semail.py:42] [semail:send_email] [ERROR]- (535, b'Error: authentication failed')
[2024-11-05 22:47:10,692] [startdriver.py:33] [startdriver:get_driver] [INFO]- start app...
[2024-11-05 22:48:04,902] [startdriver.py:29] [startdriver:get_driver] [INFO]- start app...
[2024-11-05 22:48:04,903] [startdriver.py:33] [startdriver:get_driver] [ERROR]- Appium服务未连接!
Traceback (most recent call last):
  File "D:\Code\1024\test\AppiumAuto\AppiumProject\common\startdriver.py", line 31, in get_driver
    driver = webdriver.Remote("http://%s:%s/wd/hub" % (data["ip"], data["port"]), capabs)
  File "C:\Users\Administrator\AppData\Local\Programs\Python\Python310\lib\site-packages\appium\webdriver\webdriver.py", line 273, in __init__
    super().__init__(
  File "C:\Users\Administrator\AppData\Local\Programs\Python\Python310\lib\site-packages\selenium\webdriver\remote\webdriver.py", line 192, in __init__
    capabilities = options.to_capabilities()
AttributeError: 'NoneType' object has no attribute 'to_capabilities'
[2024-11-05 22:51:47,978] [startdriver.py:38] [startdriver:get_driver] [INFO]- start app...
[2024-11-05 22:51:47,979] [startdriver.py:42] [startdriver:get_driver] [ERROR]- Appium服务未连接!
Traceback (most recent call last):
  File "D:\Code\1024\test\AppiumAuto\AppiumProject\common\startdriver.py", line 40, in get_driver
    driver = webdriver.Remote(f"http://{data['ip']}:{data['port']}/wd/hub", capabs)
  File "C:\Users\Administrator\AppData\Local\Programs\Python\Python310\lib\site-packages\appium\webdriver\webdriver.py", line 273, in __init__
    super().__init__(
  File "C:\Users\Administrator\AppData\Local\Programs\Python\Python310\lib\site-packages\selenium\webdriver\remote\webdriver.py", line 192, in __init__
    capabilities = options.to_capabilities()
AttributeError: 'NoneType' object has no attribute 'to_capabilities'
[2024-11-05 22:53:06,528] [startdriver.py:38] [startdriver:get_driver] [INFO]- start app...
[2024-11-05 22:53:06,529] [startdriver.py:42] [startdriver:get_driver] [ERROR]- Appium服务未连接!
Traceback (most recent call last):
  File "D:\Code\1024\test\AppiumAuto\AppiumProject\common\startdriver.py", line 40, in get_driver
    driver = webdriver.Remote(f"http://{data['ip']}:{data['port']}/wd/hub", capabs)
  File "C:\Users\Administrator\AppData\Local\Programs\Python\Python310\lib\site-packages\appium\webdriver\webdriver.py", line 273, in __init__
    super().__init__(
  File "C:\Users\Administrator\AppData\Local\Programs\Python\Python310\lib\site-packages\selenium\webdriver\remote\webdriver.py", line 192, in __init__
    capabilities = options.to_capabilities()
AttributeError: 'NoneType' object has no attribute 'to_capabilities'
[2024-11-05 22:56:42,633] [startdriver.py:38] [startdriver:get_driver] [INFO]- start app...
[2024-11-05 22:56:42,634] [startdriver.py:42] [startdriver:get_driver] [ERROR]- Appium服务未连接!
Traceback (most recent call last):
  File "D:\Code\1024\test\AppiumAuto\AppiumProject\common\startdriver.py", line 40, in get_driver
    driver = webdriver.Remote(f"http://{data['ip']}:{data['port']}/wd/hub", capabs)
  File "C:\Users\Administrator\AppData\Local\Programs\Python\Python310\lib\site-packages\appium\webdriver\webdriver.py", line 273, in __init__
    super().__init__(
  File "C:\Users\Administrator\AppData\Local\Programs\Python\Python310\lib\site-packages\selenium\webdriver\remote\webdriver.py", line 192, in __init__
    capabilities = options.to_capabilities()
AttributeError: 'NoneType' object has no attribute 'to_capabilities'
[2024-11-05 22:56:47,258] [startdriver.py:38] [startdriver:get_driver] [INFO]- start app...
[2024-11-05 22:56:47,258] [startdriver.py:42] [startdriver:get_driver] [ERROR]- Appium服务未连接!
Traceback (most recent call last):
  File "D:\Code\1024\test\AppiumAuto\AppiumProject\common\startdriver.py", line 40, in get_driver
    driver = webdriver.Remote(f"http://{data['ip']}:{data['port']}/wd/hub", capabs)
  File "C:\Users\Administrator\AppData\Local\Programs\Python\Python310\lib\site-packages\appium\webdriver\webdriver.py", line 273, in __init__
    super().__init__(
  File "C:\Users\Administrator\AppData\Local\Programs\Python\Python310\lib\site-packages\selenium\webdriver\remote\webdriver.py", line 192, in __init__
    capabilities = options.to_capabilities()
AttributeError: 'NoneType' object has no attribute 'to_capabilities'
[2024-11-05 22:57:45,599] [startdriver.py:38] [startdriver:get_driver] [INFO]- start app...
[2024-11-05 22:57:45,600] [startdriver.py:42] [startdriver:get_driver] [ERROR]- Appium服务未连接!
Traceback (most recent call last):
  File "D:\Code\1024\test\AppiumAuto\AppiumProject\common\startdriver.py", line 40, in get_driver
    driver = webdriver.Remote(f"http://{data['ip']}:{data['port']}/wd/hub", capabs)
  File "C:\Users\Administrator\AppData\Local\Programs\Python\Python310\lib\site-packages\appium\webdriver\webdriver.py", line 273, in __init__
    super().__init__(
  File "C:\Users\Administrator\AppData\Local\Programs\Python\Python310\lib\site-packages\selenium\webdriver\remote\webdriver.py", line 192, in __init__
    capabilities = options.to_capabilities()
AttributeError: 'NoneType' object has no attribute 'to_capabilities'
[2024-11-05 22:59:55,562] [startdriver.py:38] [startdriver:get_driver] [INFO]- start app...
[2024-11-05 22:59:55,562] [startdriver.py:42] [startdriver:get_driver] [ERROR]- Appium服务未连接!
Traceback (most recent call last):
  File "D:\Code\1024\test\AppiumAuto\AppiumProject\common\startdriver.py", line 40, in get_driver
    driver = webdriver.Remote(f"http://{data['ip']}:{data['port']}/wd/hub", capabs)
  File "C:\Users\Administrator\AppData\Local\Programs\Python\Python310\lib\site-packages\appium\webdriver\webdriver.py", line 273, in __init__
    super().__init__(
  File "C:\Users\Administrator\AppData\Local\Programs\Python\Python310\lib\site-packages\selenium\webdriver\remote\webdriver.py", line 192, in __init__
    capabilities = options.to_capabilities()
AttributeError: 'NoneType' object has no attribute 'to_capabilities'
[2024-11-05 23:00:34,198] [startdriver.py:38] [startdriver:get_driver] [INFO]- start app...
[2024-11-05 23:01:58,452] [startdriver.py:42] [startdriver:get_driver] [ERROR]- Appium服务未连接!
Traceback (most recent call last):
  File "D:\Code\1024\test\AppiumAuto\AppiumProject\common\startdriver.py", line 40, in get_driver
    driver = webdriver.Remote(f"http://{data['ip']}:{data['port']}/wd/hub", capabs)
  File "C:\Users\Administrator\AppData\Local\Programs\Python\Python310\lib\site-packages\appium\webdriver\webdriver.py", line 273, in __init__
    super().__init__(
  File "C:\Users\Administrator\AppData\Local\Programs\Python\Python310\lib\site-packages\selenium\webdriver\remote\webdriver.py", line 192, in __init__
    capabilities = options.to_capabilities()
AttributeError: 'NoneType' object has no attribute 'to_capabilities'
[2024-11-05 23:23:05,559] [startdriver.py:38] [startdriver:get_driver] [INFO]- start app...
[2024-11-05 23:23:15,005] [startdriver.py:45] [startdriver:get_driver] [INFO]- 连接Appium：http://127.0.0.1:4723/wd/hub
[2024-11-05 23:23:15,011] [UnittestFunc.py:18] [UnittestFunc:setUp] [INFO]- 正在执行测试用例...
