[2024-10-23 22:16:42,560] [startdriver.py:33] [startdriver:get_driver] [INFO]- start app...
[2024-10-23 22:16:56,457] [startdriver.py:40] [startdriver:get_driver] [INFO]- 连接Appium：http://127.0.0.1:4723/wd/hub
[2024-10-23 22:16:56,466] [UnittestFunc.py:18] [UnittestFunc:setUp] [INFO]- 正在执行测试用例...
[2024-10-23 22:17:09,017] [semail.py:42] [semail:send_email] [ERROR]- (535, b'Error: authentication failed')
[2024-10-23 22:17:28,260] [startdriver.py:33] [startdriver:get_driver] [INFO]- start app...
[2024-10-23 22:17:35,068] [startdriver.py:40] [startdriver:get_driver] [INFO]- 连接Appium：http://127.0.0.1:4723/wd/hub
[2024-10-23 22:17:35,073] [UnittestFunc.py:18] [UnittestFunc:setUp] [INFO]- 正在执行测试用例...
[2024-10-23 22:17:48,397] [semail.py:42] [semail:send_email] [ERROR]- (535, b'Error: authentication failed')
[2024-10-23 22:17:59,517] [startdriver.py:33] [startdriver:get_driver] [INFO]- start app...
[2024-10-23 22:18:06,176] [startdriver.py:40] [startdriver:get_driver] [INFO]- 连接Appium：http://127.0.0.1:4723/wd/hub
[2024-10-23 22:18:06,180] [UnittestFunc.py:18] [UnittestFunc:setUp] [INFO]- 正在执行测试用例...
[2024-10-23 22:18:20,867] [semail.py:42] [semail:send_email] [ERROR]- (535, b'Error: authentication failed')
